# 错误处理(Error Handling)

> 我早就知道无论我活多久,这种事情迟早总会发生的
> --George Bernard Shaw on dying

原文
> I knew if I stayed around long enough, something like this would happen

Rust中的错误处理与其自身的简短章节不同.这里没有任何困难的想法,只是对你来说可能不熟悉.本章介绍Rust中的两种不同类型的错误处理:panic和`Result`.

使用`Result`处理普通错误.这些通常是由程序外的事情引起的,例如错误的输入,网络中断或权限问题.发生这种情况并不取决于我们;即使是无错误的程序也会不时遇到它们.本章的大部分内容都是针对这种错误的.不过,我们会介绍panic,因为它更简单.

panic是针对另一种错误,那种 *不应该发生(should never happen)* 的错误.

## Panic

一个程序在遇到一些非常混乱的事情时会恐慌(panics),程序本身一定存在错误.就像是:

- 数组访问越界

- 整数除以零

- 在碰巧为`None`的`Option`上调用`.unwrap()`

- 断言失败

(还有宏`panic!()`,对于你自己的代码发现它出错的情况,你因此需要直接触发panic.`panic!()`接受可选的`println!()`式参数,用于构建错误信息.)

这些条件的共同之处在于它们都是--不够细致--程序员的错误.一个好的经验法则是:"Don't panic".

但我们都会犯错.当这些不该发生的错误确实发生了--然后呢?值得注意的是,Rust给了你一个选择.当发生恐慌时,Rust可以展开堆栈,也可以中止进程.展开是默认的.

### 展开(Unwinding)

当海盗瓜分从突袭中所得战利品时,船长获得了一半的战利品.普通船员获得另一半的平等份额.(海盗讨厌分数，所以如果任何一个分裂都没有出现,结果会向下舍入,其余部分将归船上的鹦鹉.)

```Rust
fn pirate_share(total: u64, crew_size: usize) -> u64 {
    let half = total / 2;
    half / crew_size as u64
}
```

这种情况可能会持续几个世纪,直到有一天发现船长是突袭的唯一幸存者.如果我们将一个为零的crew_size传递给这个函数,它将除以零.在C++中,这将是未定义行为.在Rust中,它会引发恐慌(panic),通常如下所示进行:

- 将错误消息打印到终端:

```Rust
thread 'main' panicked at 'attempt to divide by zero', pirates.rs:3780
note: Run with `RUST_BACKTRACE=1` for a backtrace.
```

如果设置`RUST_BACKTRACE`环境变量,正如消息所示,Rust也会在此时转储堆栈.

- 堆栈已解开.这很像C++异常处理.

当前函数正在使用的任何临时值,局部变量或参数将按照与创建它们相反的顺序顺序被删除.删除值只是意味着在它之后进行清理:程序使用的任何`String`或`Vec`都被释放,任何打开的`File`都被关闭,等等.也调用用户定义的`drop`方法;请参阅第282页的"Drop".在`pirate_share()`的特定情况下,没有什么可以清理的.

清除当前函数调用后,我们继续它的调用者,以相同的方式删除它的变量和参数.然后 *这个(that)* 函数的调用者,依此类推.

- 最后,线程退出.如果恐慌线程是主线程,则整个进程退出(使用非零退出代码).

也许 *恐慌(panic)* 是这个有序过程的误导性名称.恐慌不是崩溃.这不是未定义行为.它更像是Java中的`RuntimeException`或C++中的`std::logic_error`.行为是定义明确的;它不应该发生.

恐慌是安全的.它不违反Rust的任何安全规则;即使你在标准库方法的中间设法恐慌,它也永远不会在内存中留下悬空指针或半初始值.我们的想法是,在发生任何不良事件 *之前(before)* ,Rust会捕获无效的数组访问,或者不管它是什么.继续进行是不安全的,所以Rust解开了堆栈.但其余的过程可以继续运行.

每个线程都有恐慌.一个线程可能会恐慌,而其他线程正在进行正常业务.在第19章中,我们将展示父线程如何在子线程发生恐慌时找出它并优雅地处理错误.

还有一种方法可以捕获堆栈展开,允许线程存活并继续运行.标准库函数`std::panic::catch_unwind()`就是这样做的.我们不会介绍如何使用它,但这是Rust的测试线程在测试中断言失败时恢复的机制.(在编写可以从C或C++调用的Rust代码时,也有必要这样做,因为跨非Rust代码中展开是未定义行为;请参阅第21章.)

理想情况下,我们都将拥有永不恐慌的无错误代码.但没有人是完美的.你可以使用线程和`catch_unwind()`来处理恐慌,使你的程序更加健壮.一个重要的警告是,这些工具只能捕获展开堆栈的恐慌.并非每次恐慌都是这样进行的.

### 中止(Aborting)

堆栈展开是默认的恐慌行为,但有两种情况下Rust不会尝试展开堆栈.

如果在第一次恐慌之后一个`.drop()`方法触发第二次恐慌而Rust仍在尝试清理,这被认为是致命的.Rust停止展开并中止整个过程.

此外,Rust的恐慌行为是可定制的.如果使用`-C panic = abort`进行编译,程序中的 *第一个(first)* 恐慌会立即中止该过程.(使用此选项,Rust不需要知道如何展开堆栈,因此这可以减少编译完的代码的大小).

这就结束了我们对Rust的恐慌的讨论.没有太多可说的,因为普通的Rust代码没有义务处理恐慌.即使你使用线程或`catch_unwind()`,所有恐慌处理代码也可能集中在少数几个地方.期望程序中的每个函数都能预测并处理自己代码中的错误是不合理的.其他因素造成的错误是另一个严重的问题.

## Result(Result)

Rust没有异常.相反,可能失败的函数有一个返回类型,如下所示:

```Rust
fn get_weather(location: LatLng) -> Result<WeatherReport, io::Error>
```

`Result`类型表示可能的失败.当我们调用`get_weather()`函数时,它将返回 *成功结果(success result)* `Ok(weather)`,`weather`是一个新的`WeatherReport`值,或返回 *错误结果(error result)* ,`Err(error_value)`,其中`error_value`是一个`io::Error`解释出了什么错.

Rust要求我们在调用此函数时编写某种错误处理.我们无法在没有对`Result`做 *某些(something)* 事情的情况下获得`WeatherReport`,如果未使用`Result`值,你将收到编译器警告.

在第10章中,我们将看到标准库如何定义`Result`以及如何定义自己的类似类型.现在,我们将采用"烹饪手册(cookbook)"方法,并专注于如何使用`Result`来获得你想要的错误处理行为.

### 捕获错误(Catching Errors)

处理`Result`的最彻底的方法是我们在第2章中展示的方式:使用`match`表达式.

```Rust
match get_weather(hometown) {
    Ok(report) => {display_weather(hometown, &report);
    }
    Err(err) => {
        println!("error querying the weather: {}", err);
        schedule_weather_retry();
    }
}
```

这是Rust相当于其他语言的`try/catch`.这是你想要正面处理错误时使用的,而不是将它们传递给你的调用者.

`match`有点冗长,因此`Result<T, E>`提供了各种在特殊情况下有用的方法.这些方法中的每一个在其实现中都具有`match`表达式.(有关结果方法的完整列表,请参阅在线文档.此处列出的方法是我们最常用的方法.)

- `result.is_ok()`和`result.is_err()`返回一个`bool`,告诉结果是成功结果还是错误结果.

- `result.ok()`返回成功值(如果有)作为`Option<T>`.如果`result`是成功结果,则返回`Some(success_value)`;否则,它返回`None`,丢弃错误值.

- `result.err()`返回错误值(如果有),作为`Option<E>`.

- `result.unwrap_or(fallback)`返回成功值,如果`result`是成功结果.否则,它返回`fallback`,丢弃错误值.

```Rust
// A fairly safe prediction for Southern California.
const THE_USUAL: WeatherReport = WeatherReport::Sunny(72);

// Get a real weather report, if possible.
// If not, fall back on the usual.
let report = get_weather(los_angeles).unwrap_or(THE_USUAL);
display_weather(los_angeles, &report);
```

这是`.ok()`的一个很好的替代方法,因为返回类型是`T`,而不是`Option<T>`.当然,只有在有适当的后备值时它才有效.

- `result.unwrap_or_else(fallback_fn)`是相同的,但不是直接传递一个后备值,而是传递一个函数或闭包.这适用于如果你不打算使用它来计算后备值会浪费的情况.仅当我们有错误结果时才会调用`fallback_fn`.

```Rust
let report =
    get_weather(hometown)
    .unwrap_or_else(|_err| vague_prediction(hometown));
```

(第14章详细介绍闭包)

- `result.unwrap()`也返回成功值,如果`result`是成功结果.但是,如果`result`是错误结果,则此方法会发生恐慌.这种方法有其用途;我们稍后会详细讨论它.

- `result.expect(message)`与`.unwrap()`相同,但允许你提供在出现恐慌情况时打印的消息.

最后,有两种方法可以借用对Result中值的引用:

- `result.as_ref()`将`Result<T, E>`转换为`Result<&T, &E>`,借用对现有结果中成功或错误值的引用.

- `result.as_mut()`是相同的,但借用了一个可变引用.返回类型是`Result<&mut T, &mut E>`.

这两个方法最有用的一个原因是此处列出的所有其他方法(`.is_ok()`和`.is_err()`除外)都会 *消耗(consume)* 它们操作的`result`.也就是说,他们通过值来接受`self`参数.有时在不破坏结果的情况下访问结果中的数据非常方便,这就是`.as_ref()`和`.as_mut()`为我们做的事情.

例如,假设你想调用`result.ok()`,但你需要将结果保持原样.你可以编写`result.as_ref().ok()`,它只是借用结果,返回`Option<&T>`而不是`Option<T>`.

### Result类型别名(Result Type Aliases)

有时你会看到Rust文档似乎省略了`Result`的错误类型:

```Rust
fn remove_file(path: &Path) -> Result<()>
```

这意味着正在使用`Result`类型别名.

类型别名是类型名称的一种简写.模块通常定义`Result`类型别名,以避免重复模块中几乎每个函数使用一致的错误类型.例如,标准库的`std::io`模块包含以下代码行:

```Rust
pub type Result<T> = result::Result<T, Error>;
```

这定义了一个公开类型`std::io::Result<T>`.它是`Result<T, E>`的别名,但硬编码`std::io::Error`作为错误类型.实际上,这意味着如果你编写`use std::io`;然后Rust会将`io::Result<String>`理解为`Result<String, io::Error>`的简写.

当在线文档中出现`Result<()>`之类的内容时,你可以单击标识符`Result`来查看正在使用的类型别名并了解错误类型.在实践中,它通常从上下文中显而易见.

### 打印错误(Printing Errors)

有时,处理错误的唯一方法是将其转储到终端并继续.我们已经展示了一种方法:

```Rust
println!("error querying the weather: {}", err);
```

标准库定义了几个具有无聊名称的错误类型:`std::io::Error`,`std::fmt::Error`,`std::str::Utf8Error`,等等.所有这些都实现了一个通用接口,即`std::error::Error`trait,这意味着它们共享以下特性:

- 它们都可以使用`println!()`打印.使用`{}`格式说明符打印错误通常仅显示简短的错误消息.或者,你可以使用`{:?}`格式说明符进行打印,以获取错误的`Debug`视图.这不是用户友好的,但包括额外的技术信息.

```Rust
// result of `println!("error: {}", err);`
error: failed to lookup address information: No address associated with

hostname
// result of `println!("error: {:?}", err);`
error: Error { repr: Custom(Custom { kind: Other, error: StringError(
"failed to lookup address information: No address associated with
hostname") }) }
```

- `err.description()`以`&str`形式返回错误消息.

- `err.cause()`返回一个`Option<&Error>`:)触发`err`的底层错误(如果有).

- 例如,网络错误可能导致银行交易失败,这可能反过来导致你的船被重新收回.如果`err.description()`是`"boat is repossessed"`,则`err.cause()`可能会返回有关失败事务的错误;它的`.description()`可能是`"failed to transfer $300 to United Yacht Supply"`,其`.cause()`可能是一个`io::Error`,其中包含导致所有大惊小怪的特定网络中断的详细信息. 第三个错误是根本原因,因此其`.cause()`方法将返回`None`.

由于标准库仅包含相当低级的功能,因此标准库错误通常为`None`.

打印错误值也不会打印出原因.如果您想确保打印所有可用信息,请使用此函数:

```Rust
use std::error::Error;
use std::io::{Write, stderr};

/// Dump an error message to `stderr`.
///
/// If another error happens while building the error message or
/// writing to `stderr`, it is ignored.
fn print_error(mut err: &Error) {
    let _ = writeln!(stderr(), "error: {}", err);
    while let Some(cause) = err.cause() {
        let _ = writeln!(stderr(), "caused by: {}", cause);
        err = cause;
    }
}
```

标准库的错误类型不包含堆栈跟踪.但`error-chain`crate可以轻松定义自己的自定义错误类型,该类型支持在创建堆栈跟踪时获取堆栈跟踪.它使用`backtrace`crate来捕获堆栈.

### 传播错误(Propagating Errors)

在我们尝试一些可能失败的大多数地方,我们不希望立即捕获并处理错误.在每个可能出错的地方使用10行`match`语句的代码太多了.

相反,如果发生错误,我们通常希望让我们的调用者处理它.我们希望错误 *传播(propagate)* 到调用堆栈.

Rust有一个`?`运算符执行此操作.你可以添加一个`?`到任何产生`Result`的表达式,例如函数调用的结果:

```Rust
let weather = get_weather(hometown)?
```

`?`的行为取决于此函数是返回成功结果还是错误结果:

- 成功时,它会打开`Result`以获得成功值.这里的`weather`的类型不是`Result<WeatherReport,io::Error>`,而只是`WeatherReport`.

- 出错时,它立即从封闭函数返回,将错误结果传递给调用链.为了确保这一点,`?`只能在具有Result返回类型的函数中使用.

`?`操作符没有什么神奇之处.你可以使用`match`表达式表达相同的内容,尽管它更加冗长:

```Rust
let weather = match get_weather(hometown) {
    Ok(success_value) => success_value,
    Err(err) => return Err(err)
};
```

这个和`?`唯一的区别是运算符是涉及类型和转换的一些细节.我们将在下一节中介绍这些细节.

在较旧的代码中,你可能会看到`try!()`宏,这是传播错误的常用方法,直到`?`运算符在Rust 1.13中引入.

```Rust
let weather = try!(get_weather(hometown));
```

宏展开为`match`表达式,和上面的一样.

很容易忘记程序中错误的可能性是多么普遍,特别是在与操作系统接口的代码中.`?`运算符有时会显示在函数的几乎每一行上:

```Rust
use std::fs;
use std::io;
use std::path::Path;
fn move_all(src: &Path, dst: &Path) -> io::Result<()> {
    for entry_result in src.read_dir()? {  // opening dir could fail
        let entry = entry_result?;         // reading dir could fail
        let dst_file = dst.join(entry.file_name());
        fs::rename(entry.path(), dst_file)?;  // renaming could fail
    }
    Ok(())  // phew!
}
```

### 使用多种错误类型(Working with Multiple Error Types)

通常,不止一件事可能出错.假设我们只是从文本文件中读取数字.

```Rust
use std::io::{self, BufRead};

/// Read integers from a text file.
/// The file should have one number on each line.
fn read_numbers(file: &mut BufRead) -> Result<Vec<i64>, io::Error> {
    let mut numbers = vec![];
    for line_result in file.lines() {
        let line = line_result?;         // reading lines can fail
        numbers.push(line.parse()?);     // parsing integers can fail
    }
    Ok(numbers)
}
```

Rust给我们一个编译器错误:

```Rust
numbers.push(line.parse()?);     // parsing integers can fail
             ^^^^^^^^^^^^^ the trait `std::convert::From<std::num::ParseIntError>`
                           is not implemented for `std::io::Error`
```

当我们达到涵盖trait的第11章时,此错误消息中的术语将更有意义.现在,请注意Rust抱怨它无法将`std::num::ParseIntError`值转换为`std::io::Error`类型.

这里的问题是从文件中读取一行并解析整数会产生两种不同的潜在错误类型.`line_result`的类型是`Result<String, std::io::Error>`.`line.parse()`的类型是`Result<i64, std::num::ParseIntError>`.我们的`read_numbers()`函数的返回类型只适用于`io::Error`.Rust试图通过将它转换为`io::Error`来处理`ParseIntError`,但是没有这样的转换,所以我们得到了一个类型错误.

有几种方法可以解决这个问题.例如,我们在第2章中用来创建Mandelbrot集的图像文件的图像包定义了它自己的错误类型`ImageError`,并实现了从`io::Error`和其他几种错误类型到`ImageError`的转换.如果你想走这条路,试试上面提到的错误`error-chain`crate,它旨在帮助你用几行代码定义好的错误类型.

一种更简单的方法是使用Rust内置的内容.所有标准库错误类型都可以转换为`Box<std::error::Error>`类型,它代表"任何错误(any error)."因此,处理多种错误类型的简单方法是定义这些类型别名:

```Rust
type GenError = Box<std::error::Error>;
type GenResult<T> = Result<T, GenError>;
```

然后,将`read_numbers()`的返回类型更改为`GenResult<Vec<i64 >>`.通过此更改,函数可以编译.`?`操作符根据需要自动将任何类型的错误转换为`GenError.

顺便说一句,`?`操作符使用你自己可以使用的标准方法进行自动转换.要将任何错误转换为`GenError`类型,请调用`GenError::from()`:

```Rust
let io_error = io::Error::new(         // make our own io::Error
    io::ErrorKind::Other, "timed out");
return Err(GenError::from(io_error
));  // manually convert to GenError
```

我们将在第13章中完整地介绍`From`trait及其`from()`方法.

`GenError`方法的缺点是返回类型不再准确地传达调用者可以预期的错误类型.调用者必须做好一切准备.

如果你正在调用一个返回`GenResult`的函数,并且你希望处理一种特定类型的错误,但让所有其他错误传播出去,请使用泛型方法`error.downcast_ref::<ErrorType>()`.它借用了对错误的引用, *如果(if)* 碰巧是你正在寻找的特定类型的错误:

```Rust
loop {
    match compile_project() {
        Ok(()) => return Ok(()),
        Err(err) => {
            if let Some(mse) = err.downcast_ref::<MissingSemicolonError>() {
                insert_semicolon_in_source_code(mse.file(), mse.line())?;
                continue;  // try again!
            }
            return Err(err);
        }
    }
}
```

许多语言都有内置的语法来实现这一点,但事实证明很少需要这样做.Rust有一个替代方法.

### 处理"不会发生"的错误(Dealing with Errors That Can't Happen")

有时我们只 *知道(know)* 错误不会发生.例如,假设我们正在编写代码来解析配置文件,并且我们发现文件中的下一个东西是数字字符串:

```Rust
if next_char.is_digit(10) {
    let start = current_index;
    current_index = skip_digits(&line, current_index);
    let digits = &line[start..current_index];
    ...
```

我们想将这个数字字符串转换为实际数字.有一种标准方法可以做到这一点:

```Rust
let num = digits.parse::<u64>();
```

现在问题是:`str.parse::<u64>()`方法不返回`u64`.它返回一个`Result`.它可能会失败,因为某些字符串不是数字.

```Rust
"bleen".parse::<u64>()  // ParseIntError: invalid digit
```

但我们碰巧知道在这种情况下,`digits`完全由数字组成.我们应该做什么?

如果我们编写的代码已经返回`GenResult`,我们可以使用`?`并忘记它.否则,我们面临着必须为不会发生的错误编写错误处理代码的恼人前景.那么最好的选择是使用`.unwrap()`,我们前面提到的`Result`方法.

```Rust
let num = digits.parse::<u64>().unwrap();
```

这就像`?`但如果我们对这个错误的判断是错误的,如果它 *可能(can)* 发生,那么在那种情况下我们就会恐慌.

事实上,我们对这个特殊情况的看法是错误的.如果输入包含足够长的数字串,那么这个数字将大到无法放入`u64`中.

```Rust
"99999999999999999999".parse::<u64>()    // overflow error
```

因此在这种特殊情况下使用`.unwrap()`将是一个错误.虚假输入不应引起恐慌.

也就是说,在`Result`值确实不能成为错误的情况下会出现这种情况.例如,在第18章中,你将看到`Write`trait为文本和二进制输出定义了一组通用方法(`.write()`和其他方法).所有这些方法都返回`io::Result`,但是如果你正好写入`Vec<u8>`,它们就不会失败.在这种情况下,可以使用`.unwrap()`或`.expect(message)`来省略`Result`.

当错误表明条件如此严重或奇怪以至于恐慌正是您想要处理它时,这些方法也很有用.

```Rust
fn print_file_age(filename: &Path,last_modified: SystemTime) {
    let age = last_modified.elapsed().expect("system clock drift");
    ...
}
```

这里,`.elapsed()`方法只有在系统时间早于创建文件时才会失败.如果文件是最近创建的,并且系统时钟在我们的程序运行时向后调整,则会发生这种情况.根据这段代码的使用方式,在这种情况下,它是一种合理的判断调用,而不是处理错误或将其传播给调用者.

### 忽略错误(Ignoring Errors)

偶尔我们只想完全忽略错误.例如,在我们的`print_error()`函数中,我们必须处理打印错误触发另一个错误的不太可能的情况.例如,如果将`stderr`传送到另一个进程,该进程被终止,可能发生这种情况.由于关于这种错误我们无能为力,我们只想忽略它;但Rust编译器会警告未使用的`Result`值:

```Rust
writeln!(stderr(), "error: {}", err);  // warning: unused result
```

习语`let _ = ...`用来沉默这个警告:

```Rust
let _ = writeln!(stderr(), "error: {}", err);  // ok, ignore result
```

### 处理main()中的错误(Handling Errors in main())

在产生`Result`的大多数地方,让错误冒泡到调用者是正确的行为.这就是为什么`?`是Rust的单个字符.正如我们所看到的,在某些程序中,它连续使用多行代码.

但是如果你传播一个足够长的错误,最终它会到达`main()`而这就是这种方法必须停止的地方.`main()`不能使用`?`因为它的返回类型不是`Result`.

